<?xml version="1.0"?>
<!-- Simplified humanoid robot model with proper physics properties for Gazebo simulation -->
<robot name="physics_humanoid">
  <!-- Base/Pelvis Link -->
  <link name="base_link">
    <inertial>
      <mass value="10.0"/>
      <origin xyz="0 0 0" rpy="0 0 0"/>
      <inertia ixx="0.333" ixy="0.0" ixz="0.0" iyy="0.333" iyz="0.0" izz="0.333"/>
    </inertial>
    <visual>
      <origin xyz="0 0 0.5" rpy="0 0 0"/>
      <geometry>
        <box size="0.3 0.2 0.4"/>
      </geometry>
      <material name="blue">
        <color rgba="0 0 1 1"/>
      </material>
    </visual>
    <collision>
      <origin xyz="0 0 0.5" rpy="0 0 0"/>
      <geometry>
        <box size="0.3 0.2 0.4"/>
      </geometry>
    </collision>
  </link>

  <!-- Torso Link -->
  <link name="torso">
    <inertial>
      <mass value="8.0"/>
      <origin xyz="0 0 0.3" rpy="0 0 0"/>
      <inertia ixx="0.267" ixy="0.0" ixz="0.0" iyy="0.267" iyz="0.0" izz="0.133"/>
    </inertial>
    <visual>
      <origin xyz="0 0 0.6" rpy="0 0 0"/>
      <geometry>
        <box size="0.25 0.15 0.6"/>
      </geometry>
      <material name="red">
        <color rgba="1 0 0 1"/>
      </material>
    </visual>
    <collision>
      <origin xyz="0 0 0.6" rpy="0 0 0"/>
      <geometry>
        <box size="0.25 0.15 0.6"/>
      </geometry>
    </collision>
  </link>

  <!-- Head Link -->
  <link name="head">
    <inertial>
      <mass value="2.0"/>
      <origin xyz="0 0 0.1" rpy="0 0 0"/>
      <inertia ixx="0.008" ixy="0.0" ixz="0.0" iyy="0.008" iyz="0.0" izz="0.008"/>
    </inertial>
    <visual>
      <origin xyz="0 0 1.1" rpy="0 0 0"/>
      <geometry>
        <sphere radius="0.15"/>
      </geometry>
      <material name="white">
        <color rgba="1 1 1 1"/>
      </material>
    </visual>
    <collision>
      <origin xyz="0 0 1.1" rpy="0 0 0"/>
      <geometry>
        <sphere radius="0.15"/>
      </geometry>
    </collision>
  </link>

  <!-- Right Upper Arm -->
  <link name="right_upper_arm">
    <inertial>
      <mass value="1.5"/>
      <origin xyz="0 -0.15 0" rpy="0 0 0"/>
      <inertia ixx="0.019" ixy="0.0" ixz="0.0" iyy="0.002" iyz="0.0" izz="0.019"/>
    </inertial>
    <visual>
      <origin xyz="0 -0.25 0.8" rpy="1.57 0 0"/>
      <geometry>
        <cylinder length="0.3" radius="0.05"/>
      </geometry>
      <material name="green">
        <color rgba="0 1 0 1"/>
      </material>
    </visual>
    <collision>
      <origin xyz="0 -0.25 0.8" rpy="1.57 0 0"/>
      <geometry>
        <cylinder length="0.3" radius="0.05"/>
      </geometry>
    </collision>
  </link>

  <!-- Right Lower Arm -->
  <link name="right_lower_arm">
    <inertial>
      <mass value="1.0"/>
      <origin xyz="0 -0.15 0" rpy="0 0 0"/>
      <inertia ixx="0.008" ixy="0.0" ixz="0.0" iyy="0.001" iyz="0.0" izz="0.008"/>
    </inertial>
    <visual>
      <origin xyz="0 -0.45 0.8" rpy="1.57 0 0"/>
      <geometry>
        <cylinder length="0.3" radius="0.04"/>
      </geometry>
      <material name="green">
        <color rgba="0 1 0 1"/>
      </material>
    </visual>
    <collision>
      <origin xyz="0 -0.45 0.8" rpy="1.57 0 0"/>
      <geometry>
        <cylinder length="0.3" radius="0.04"/>
      </geometry>
    </collision>
  </link>

  <!-- Left Upper Arm -->
  <link name="left_upper_arm">
    <inertial>
      <mass value="1.5"/>
      <origin xyz="0 0.15 0" rpy="0 0 0"/>
      <inertia ixx="0.019" ixy="0.0" ixz="0.0" iyy="0.002" iyz="0.0" izz="0.019"/>
    </inertial>
    <visual>
      <origin xyz="0 0.25 0.8" rpy="-1.57 0 0"/>
      <geometry>
        <cylinder length="0.3" radius="0.05"/>
      </geometry>
      <material name="green">
        <color rgba="0 1 0 1"/>
      </material>
    </visual>
    <collision>
      <origin xyz="0 0.25 0.8" rpy="-1.57 0 0"/>
      <geometry>
        <cylinder length="0.3" radius="0.05"/>
      </geometry>
    </collision>
  </link>

  <!-- Left Lower Arm -->
  <link name="left_lower_arm">
    <inertial>
      <mass value="1.0"/>
      <origin xyz="0 0.15 0" rpy="0 0 0"/>
      <inertia ixx="0.008" ixy="0.0" ixz="0.0" iyy="0.001" iyz="0.0" izz="0.008"/>
    </inertial>
    <visual>
      <origin xyz="0 0.45 0.8" rpy="-1.57 0 0"/>
      <geometry>
        <cylinder length="0.3" radius="0.04"/>
      </geometry>
      <material name="green">
        <color rgba="0 1 0 1"/>
      </material>
    </visual>
    <collision>
      <origin xyz="0 0.45 0.8" rpy="-1.57 0 0"/>
      <geometry>
        <cylinder length="0.3" radius="0.04"/>
      </geometry>
    </collision>
  </link>

  <!-- Right Thigh -->
  <link name="right_thigh">
    <inertial>
      <mass value="3.0"/>
      <origin xyz="0 0 -0.2" rpy="0 0 0"/>
      <inertia ixx="0.04" ixy="0.0" ixz="0.0" iyy="0.04" iyz="0.0" izz="0.005"/>
    </inertial>
    <visual>
      <origin xyz="0.1 0 0.2" rpy="0 0 0"/>
      <geometry>
        <cylinder length="0.4" radius="0.06"/>
      </geometry>
      <material name="yellow">
        <color rgba="1 1 0 1"/>
      </material>
    </visual>
    <collision>
      <origin xyz="0.1 0 0.2" rpy="0 0 0"/>
      <geometry>
        <cylinder length="0.4" radius="0.06"/>
      </geometry>
    </collision>
  </link>

  <!-- Right Shin -->
  <link name="right_shin">
    <inertial>
      <mass value="2.5"/>
      <origin xyz="0 0 -0.2" rpy="0 0 0"/>
      <inertia ixx="0.033" ixy="0.0" ixz="0.0" iyy="0.033" iyz="0.0" izz="0.004"/>
    </inertial>
    <visual>
      <origin xyz="0.1 0 -0.2" rpy="0 0 0"/>
      <geometry>
        <cylinder length="0.4" radius="0.05"/>
      </geometry>
      <material name="yellow">
        <color rgba="1 1 0 1"/>
      </material>
    </visual>
    <collision>
      <origin xyz="0.1 0 -0.2" rpy="0 0 0"/>
      <geometry>
        <cylinder length="0.4" radius="0.05"/>
      </geometry>
    </collision>
  </link>

  <!-- Right Foot -->
  <link name="right_foot">
    <inertial>
      <mass value="1.0"/>
      <origin xyz="0.05 0 0" rpy="0 0 0"/>
      <inertia ixx="0.005" ixy="0.0" ixz="0.0" iyy="0.008" iyz="0.0" izz="0.008"/>
    </inertial>
    <visual>
      <origin xyz="0.15 0 -0.45" rpy="0 0 0"/>
      <geometry>
        <box size="0.15 0.1 0.05"/>
      </geometry>
      <material name="black">
        <color rgba="0 0 0 1"/>
      </material>
    </visual>
    <collision>
      <origin xyz="0.15 0 -0.45" rpy="0 0 0"/>
      <geometry>
        <box size="0.15 0.1 0.05"/>
      </geometry>
    </collision>
  </link>

  <!-- Left Thigh -->
  <link name="left_thigh">
    <inertial>
      <mass value="3.0"/>
      <origin xyz="0 0 -0.2" rpy="0 0 0"/>
      <inertia ixx="0.04" ixy="0.0" ixz="0.0" iyy="0.04" iyz="0.0" izz="0.005"/>
    </inertial>
    <visual>
      <origin xyz="-0.1 0 0.2" rpy="0 0 0"/>
      <geometry>
        <cylinder length="0.4" radius="0.06"/>
      </geometry>
      <material name="yellow">
        <color rgba="1 1 0 1"/>
      </material>
    </visual>
    <collision>
      <origin xyz="-0.1 0 0.2" rpy="0 0 0"/>
      <geometry>
        <cylinder length="0.4" radius="0.06"/>
      </geometry>
    </collision>
  </link>

  <!-- Left Shin -->
  <link name="left_shin">
    <inertial>
      <mass value="2.5"/>
      <origin xyz="0 0 -0.2" rpy="0 0 0"/>
      <inertia ixx="0.033" ixy="0.0" ixz="0.0" iyy="0.033" iyz="0.0" izz="0.004"/>
    </inertial>
    <visual>
      <origin xyz="-0.1 0 -0.2" rpy="0 0 0"/>
      <geometry>
        <cylinder length="0.4" radius="0.05"/>
      </geometry>
      <material name="yellow">
        <color rgba="1 1 0 1"/>
      </material>
    </visual>
    <collision>
      <origin xyz="-0.1 0 -0.2" rpy="0 0 0"/>
      <geometry>
        <cylinder length="0.4" radius="0.05"/>
      </geometry>
    </collision>
  </link>

  <!-- Left Foot -->
  <link name="left_foot">
    <inertial>
      <mass value="1.0"/>
      <origin xyz="0.05 0 0" rpy="0 0 0"/>
      <inertia ixx="0.005" ixy="0.0" ixz="0.0" iyy="0.008" iyz="0.0" izz="0.008"/>
    </inertial>
    <visual>
      <origin xyz="-0.05 0 -0.45" rpy="0 0 0"/>
      <geometry>
        <box size="0.15 0.1 0.05"/>
      </geometry>
      <material name="black">
        <color rgba="0 0 0 1"/>
      </material>
    </visual>
    <collision>
      <origin xyz="-0.05 0 -0.45" rpy="0 0 0"/>
      <geometry>
        <box size="0.15 0.1 0.05"/>
      </geometry>
    </collision>
  </link>

  <!-- Joints -->
  <joint name="torso_joint" type="fixed">
    <parent link="base_link"/>
    <child link="torso"/>
    <origin xyz="0 0 0.7" rpy="0 0 0"/>
  </joint>

  <joint name="head_joint" type="fixed">
    <parent link="torso"/>
    <child link="head"/>
    <origin xyz="0 0 0.9" rpy="0 0 0"/>
  </joint>

  <joint name="right_shoulder_joint" type="revolute">
    <parent link="torso"/>
    <child link="right_upper_arm"/>
    <origin xyz="0 -0.15 0.7" rpy="0 0 0"/>
    <axis xyz="0 1 0"/>
    <limit lower="-1.57" upper="1.57" effort="50" velocity="1.0"/>
    <dynamics damping="0.1" friction="0.0"/>
  </joint>

  <joint name="right_elbow_joint" type="revolute">
    <parent link="right_upper_arm"/>
    <child link="right_lower_arm"/>
    <origin xyz="0 -0.3 0" rpy="0 0 0"/>
    <axis xyz="0 1 0"/>
    <limit lower="-2.0" upper="0.5" effort="30" velocity="1.0"/>
    <dynamics damping="0.1" friction="0.0"/>
  </joint>

  <joint name="left_shoulder_joint" type="revolute">
    <parent link="torso"/>
    <child link="left_upper_arm"/>
    <origin xyz="0 0.15 0.7" rpy="0 0 0"/>
    <axis xyz="0 1 0"/>
    <limit lower="-1.57" upper="1.57" effort="50" velocity="1.0"/>
    <dynamics damping="0.1" friction="0.0"/>
  </joint>

  <joint name="left_elbow_joint" type="revolute">
    <parent link="left_upper_arm"/>
    <child link="left_lower_arm"/>
    <origin xyz="0 0.3 0" rpy="0 0 0"/>
    <axis xyz="0 1 0"/>
    <limit lower="-2.0" upper="0.5" effort="30" velocity="1.0"/>
    <dynamics damping="0.1" friction="0.0"/>
  </joint>

  <joint name="right_hip_joint" type="revolute">
    <parent link="base_link"/>
    <child link="right_thigh"/>
    <origin xyz="0.1 0 0.4" rpy="0 0 0"/>
    <axis xyz="0 1 0"/>
    <limit lower="-1.0" upper="1.0" effort="100" velocity="1.0"/>
    <dynamics damping="0.2" friction="0.0"/>
  </joint>

  <joint name="right_knee_joint" type="revolute">
    <parent link="right_thigh"/>
    <child link="right_shin"/>
    <origin xyz="0 0 -0.4" rpy="0 0 0"/>
    <axis xyz="0 1 0"/>
    <limit lower="-2.0" upper="0.5" effort="80" velocity="1.0"/>
    <dynamics damping="0.2" friction="0.0"/>
  </joint>

  <joint name="right_ankle_joint" type="revolute">
    <parent link="right_shin"/>
    <child link="right_foot"/>
    <origin xyz="0 0 -0.45" rpy="0 0 0"/>
    <axis xyz="1 0 0"/>
    <limit lower="-0.5" upper="0.5" effort="40" velocity="1.0"/>
    <dynamics damping="0.1" friction="0.0"/>
  </joint>

  <joint name="left_hip_joint" type="revolute">
    <parent link="base_link"/>
    <child link="left_thigh"/>
    <origin xyz="-0.1 0 0.4" rpy="0 0 0"/>
    <axis xyz="0 1 0"/>
    <limit lower="-1.0" upper="1.0" effort="100" velocity="1.0"/>
    <dynamics damping="0.2" friction="0.0"/>
  </joint>

  <joint name="left_knee_joint" type="revolute">
    <parent link="left_thigh"/>
    <child link="left_shin"/>
    <origin xyz="0 0 -0.4" rpy="0 0 0"/>
    <axis xyz="0 1 0"/>
    <limit lower="-2.0" upper="0.5" effort="80" velocity="1.0"/>
    <dynamics damping="0.2" friction="0.0"/>
  </joint>

  <joint name="left_ankle_joint" type="revolute">
    <parent link="left_shin"/>
    <child link="left_foot"/>
    <origin xyz="0 0 -0.45" rpy="0 0 0"/>
    <axis xyz="1 0 0"/>
    <limit lower="-0.5" upper="0.5" effort="40" velocity="1.0"/>
    <dynamics damping="0.1" friction="0.0"/>
  </joint>

  <!-- Gazebo-specific elements -->
  <gazebo reference="base_link">
    <material>Gazebo/Blue</material>
    <mu1>0.8</mu1>
    <mu2>0.8</mu2>
    <kp>1000000.0</kp>
    <kd>100.0</kd>
  </gazebo>

  <gazebo reference="torso">
    <material>Gazebo/Red</material>
    <mu1>0.8</mu1>
    <mu2>0.8</mu2>
    <kp>1000000.0</kp>
    <kd>100.0</kd>
  </gazebo>

  <gazebo reference="head">
    <material>Gazebo/White</material>
    <mu1>0.8</mu1>
    <mu2>0.8</mu2>
    <kp>1000000.0</kp>
    <kd>100.0</kd>
  </gazebo>

  <gazebo reference="right_upper_arm">
    <material>Gazebo/Green</material>
    <mu1>0.8</mu1>
    <mu2>0.8</mu2>
    <kp>1000000.0</kp>
    <kd>100.0</kd>
  </gazebo>

  <gazebo reference="right_lower_arm">
    <material>Gazebo/Green</material>
    <mu1>0.8</mu1>
    <mu2>0.8</mu2>
    <kp>1000000.0</kp>
    <kd>100.0</kd>
  </gazebo>

  <gazebo reference="left_upper_arm">
    <material>Gazebo/Green</material>
    <mu1>0.8</mu1>
    <mu2>0.8</mu2>
    <kp>1000000.0</kp>
    <kd>100.0</kd>
  </gazebo>

  <gazebo reference="left_lower_arm">
    <material>Gazebo/Green</material>
    <mu1>0.8</mu1>
    <mu2>0.8</mu2>
    <kp>1000000.0</kp>
    <kd>100.0</kd>
  </gazebo>

  <gazebo reference="right_thigh">
    <material>Gazebo/Yellow</material>
    <mu1>0.8</mu1>
    <mu2>0.8</mu2>
    <kp>1000000.0</kp>
    <kd>100.0</kd>
  </gazebo>

  <gazebo reference="right_shin">
    <material>Gazebo/Yellow</material>
    <mu1>0.8</mu1>
    <mu2>0.8</mu2>
    <kp>1000000.0</kp>
    <kd>100.0</kd>
  </gazebo>

  <gazebo reference="right_foot">
    <material>Gazebo/Black</material>
    <mu1>0.9</mu1>
    <mu2>0.9</mu2>
    <kp>1000000.0</kp>
    <kd>100.0</kd>
    <fdir1>1 0 0</fdir1>
  </gazebo>

  <gazebo reference="left_thigh">
    <material>Gazebo/Yellow</material>
    <mu1>0.8</mu1>
    <mu2>0.8</mu2>
    <kp>1000000.0</kp>
    <kd>100.0</kd>
  </gazebo>

  <gazebo reference="left_shin">
    <material>Gazebo/Yellow</material>
    <mu1>0.8</mu1>
    <mu2>0.8</mu2>
    <kp>1000000.0</kp>
    <kd>100.0</kd>
  </gazebo>

  <gazebo reference="left_foot">
    <material>Gazebo/Black</material>
    <mu1>0.9</mu1>
    <mu2>0.9</mu2>
    <kp>1000000.0</kp>
    <kd>100.0</kd>
    <fdir1>1 0 0</fdir1>
  </gazebo>

  <!-- Gazebo plugin for ROS control -->
  <gazebo>
    <plugin name="gazebo_ros_control" filename="libgazebo_ros_control.so">
      <robotNamespace>/physics_humanoid</robotNamespace>
    </plugin>
  </gazebo>
</robot>